I'm sorry, but an uncaught exception occurred.

While running game code:
  File "game/script.rpy", line 186, in script call
    call screen dungeon_command
  File "game/script.rpy", line 217, in script
    python: # Rounds code
  File "game/script.rpy", line 231, in <module>
    enemyTurn(n)
  File "game/CombatSystem.rpy", line 669, in enemyTurn
    enemytarget = random.choices(party_targets, weights = party_weights, k=1)[0]
IndexError: list index out of range

-- Full Traceback ------------------------------------------------------------

Full traceback:
  File "game/script.rpy", line 186, in script call
    call screen dungeon_command
  File "game/script.rpy", line 217, in script
    python: # Rounds code
  File "E:\Ren Py\renpy-8.1.3-sdk\renpy\ast.py", line 1138, in execute
    renpy.python.py_exec_bytecode(self.code.bytecode, self.hide, store=self.store)
  File "E:\Ren Py\renpy-8.1.3-sdk\renpy\python.py", line 1122, in py_exec_bytecode
    exec(bytecode, globals, locals)
  File "game/script.rpy", line 231, in <module>
    enemyTurn(n)
  File "game/CombatSystem.rpy", line 669, in enemyTurn
    enemytarget = random.choices(party_targets, weights = party_weights, k=1)[0]
  File "/home/tom/ab/renpy-build-fix/tmp/install.linux-x86_64/lib/python3.9/random.py", line 500, in choices
IndexError: list index out of range

Windows-10-10.0.19041 AMD64
Ren'Py 8.1.3.23091805
Dungeons of Hundwick 0.13.1_Webp_update
Mon Dec 25 16:45:37 2023
