I'm sorry, but an uncaught exception occurred.

While running game code:
  File "game/script.rpy", line 214, in script call
    call screen dungeon_command
  File "game/script.rpy", line 257, in script
    python: # Rounds code
  File "game/script.rpy", line 310, in <module>
    applyDamage(n)
  File "game/CombatSystem.rpy", line 1045, in applyDamage
    renpý.pause(0.5)
NameError: name 'renpý' is not defined

-- Full Traceback ------------------------------------------------------------

Full traceback:
  File "game/script.rpy", line 214, in script call
    call screen dungeon_command
  File "game/script.rpy", line 257, in script
    python: # Rounds code
  File "E:\Ren Py\renpy-8.1.3-sdk\renpy\ast.py", line 1138, in execute
    renpy.python.py_exec_bytecode(self.code.bytecode, self.hide, store=self.store)
  File "E:\Ren Py\renpy-8.1.3-sdk\renpy\python.py", line 1122, in py_exec_bytecode
    exec(bytecode, globals, locals)
  File "game/script.rpy", line 310, in <module>
    applyDamage(n)
  File "game/CombatSystem.rpy", line 1045, in applyDamage
    renpý.pause(0.5)
NameError: name 'renpý' is not defined

Windows-10-10.0.19041 AMD64
Ren'Py 8.1.3.23091805
Dungeons of Hundwick 0.14_Combat_Update
Fri Dec 29 08:45:42 2023
